<?xml version="1.0" ?>
<!-- =================================================================================== -->
<!-- |    This document was autogenerated by xacro from /opt/ros/converging_noether_demo-noetic/share/converging_polishing_workcell/urdf/converging_polishing_workcell.xacro | -->
<!-- |    EDITING THIS FILE BY HAND IS NOT RECOMMENDED                                 | -->
<!-- =================================================================================== -->
<robot name="converging_polishing_workcell">
  <!-- <xacro:include filename="$(find robotnik_sensors)/urdf/intel_d435.urdf.xacro"/>
  <xacro:include filename="$(find robotnik_sensors)/urdf/utils/inertia.urdf.xacro"/>
  <xacro:include filename="$(find robotnik_sensors)/urdf/utils/material.urdf.xacro"/> -->
  <link name="world"/>
  <link name="table">
    <visual>
      <geometry>
        <box size="2.0 0.95 0.9"/>
      </geometry>
      <origin rpy="0 0 0" xyz="0.00 0.0 -0.45"/>
      <material name="gray">
        <color rgba="0.5 0.5 0.5 1"/>
      </material>
    </visual>
    <collision>
      <geometry>
        <box size="2.0 0.95 0.9"/>
      </geometry>
      <origin rpy="0 0 0" xyz="0.00 0.0 -0.45"/>
    </collision>
  </link>
  <link name="column">
    <visual>
      <geometry>
        <box size="0.18 0.09 2.11"/>
      </geometry>
      <origin rpy="0 0 0" xyz="0.00 -0.042 0.141"/>
      <material name="gray">
        <color rgba="0.5 0.5 0.5 1"/>
      </material>
    </visual>
    <collision>
      <geometry>
        <box size="0.18 0.09 2.11"/>
      </geometry>
      <origin rpy="0 0 0" xyz="0.00 -0.042 0.141"/>
    </collision>
  </link>
  <joint name="column" type="fixed">
    <parent link="table"/>
    <child link="column"/>
    <origin xyz="0.545 -.4725  0"/>
  </joint>
  <joint name="table" type="fixed">
    <parent link="world"/>
    <child link="table"/>
    <origin rpy="0 0 3.141592653589793" xyz="1.0030000000000001 0.41100000000000003 0"/>
  </joint>
  <joint name="cuña" type="fixed">
    <parent link="column"/>
    <child link="cuña_base_link"/>
    <!-- height of column - height from top of column to top of cuña -->
    <origin rpy="-1.5707963267948966 -1.5707963267948966 0" xyz="0 0 1.133"/>
  </joint>
  <link name="cuña_base_link"/>
  <link name="cuña_body">
    <visual>
      <geometry>
        <mesh filename="package://converging_polishing_workcell/meshes/collision/cuña.stl" scale="0.001 0.001 0.001"/>
      </geometry>
      <material name="gray">
        <color rgba="0.5 0.5 0.5 1"/>
      </material>
    </visual>
    <collision>
      <geometry>
        <mesh filename="package://converging_polishing_workcell/meshes/collision/cuña.stl" scale="0.001 0.001 0.001"/>
      </geometry>
    </collision>
    <inertial>
      <mass value="50.0"/>
      <inertia ixx="10.00" ixy="0.00" ixz="0.00" iyy="10.00" iyz="0.00" izz="10.00"/>
      <origin rpy="0 0 0" xyz="0.0 0.0 -0.5"/>
    </inertial>
  </link>
  <joint name="cuña_body" type="fixed">
    <parent link="cuña_base_link"/>
    <child link="cuña_body"/>
    <origin rpy="0 -1.5707963267948966 0" xyz="0 0 0"/>
  </joint>
  <link name="cuña_tool0"/>
  <joint name="cuña_tool0" type="fixed">
    <parent link="cuña_body"/>
    <child link="cuña_tool0"/>
    <origin rpy="0 1.0471975511965976 0" xyz="0.07250000000000001 0 0.11674682452694517"/>
  </joint>
  <!--
    Base UR robot series xacro macro.

    NOTE: this is NOT a URDF. It cannot directly be loaded by consumers
    expecting a flattened '.urdf' file. See the top-level '.xacro' for that
    (but note: that .xacro must still be processed by the xacro command).

    For use in '.launch' files: use one of the 'load_urX.launch' convenience
    launch files.

    This file models the base kinematic chain of a UR robot, which then gets
    parameterised by various configuration files to convert it into a UR3(e),
    UR5(e), UR10(e) or UR16e.

    NOTE: the default kinematic parameters (ie: link lengths, frame locations,
    offets, etc) do not correspond to any particular robot. They are defaults
    only. There WILL be non-zero offsets between the Forward Kinematics results
    in TF (ie: robot_state_publisher) and the values reported by the Teach
    Pendant.

    For accurate (and robot-specific) transforms, the 'kinematics_parameters_file'
    parameter MUST point to a .yaml file containing the appropriate values for
    the targetted robot.

    If using the UniversalRobots/Universal_Robots_ROS_Driver, follow the steps
    described in the readme of that repository to extract the kinematic
    calibration from the controller and generate the required .yaml file.

    Main author of the migration to yaml configs: Ludovic Delval.

    Contributors to previous versions (in no particular order):

     - Felix Messmer
     - Kelsey Hawkins
     - Wim Meeussen
     - Shaun Edwards
     - Nadia Hammoudeh Garcia
     - Dave Hershberger
     - G. vd. Hoorn
     - Philip Long
     - Dave Coleman
     - Miguel Prada
     - Mathias Luedtke
     - Marcel Schnirring
     - Felix von Drigalski
     - Felix Exner
     - Jimmy Da Silva
     - Ajit Krisshna N L
     - Muhammad Asif Rana
  -->
  <!--
    NOTE: the macro defined in this file is NOT part of the public API of this
          package. Users CANNOT rely on this file being available, or stored in
          this location. Nor can they rely on the existence of the macro.
  -->
  <transmission name="shoulder_pan_trans">
    <type>transmission_interface/SimpleTransmission</type>
    <joint name="shoulder_pan_joint">
      <hardwareInterface>hardware_interface/PositionJointInterface</hardwareInterface>
    </joint>
    <actuator name="shoulder_pan_motor">
      <mechanicalReduction>1</mechanicalReduction>
    </actuator>
  </transmission>
  <transmission name="shoulder_lift_trans">
    <type>transmission_interface/SimpleTransmission</type>
    <joint name="shoulder_lift_joint">
      <hardwareInterface>hardware_interface/PositionJointInterface</hardwareInterface>
    </joint>
    <actuator name="shoulder_lift_motor">
      <mechanicalReduction>1</mechanicalReduction>
    </actuator>
  </transmission>
  <transmission name="elbow_trans">
    <type>transmission_interface/SimpleTransmission</type>
    <joint name="elbow_joint">
      <hardwareInterface>hardware_interface/PositionJointInterface</hardwareInterface>
    </joint>
    <actuator name="elbow_motor">
      <mechanicalReduction>1</mechanicalReduction>
    </actuator>
  </transmission>
  <transmission name="wrist_1_trans">
    <type>transmission_interface/SimpleTransmission</type>
    <joint name="wrist_1_joint">
      <hardwareInterface>hardware_interface/PositionJointInterface</hardwareInterface>
    </joint>
    <actuator name="wrist_1_motor">
      <mechanicalReduction>1</mechanicalReduction>
    </actuator>
  </transmission>
  <transmission name="wrist_2_trans">
    <type>transmission_interface/SimpleTransmission</type>
    <joint name="wrist_2_joint">
      <hardwareInterface>hardware_interface/PositionJointInterface</hardwareInterface>
    </joint>
    <actuator name="wrist_2_motor">
      <mechanicalReduction>1</mechanicalReduction>
    </actuator>
  </transmission>
  <transmission name="wrist_3_trans">
    <type>transmission_interface/SimpleTransmission</type>
    <joint name="wrist_3_joint">
      <hardwareInterface>hardware_interface/PositionJointInterface</hardwareInterface>
    </joint>
    <actuator name="wrist_3_motor">
      <mechanicalReduction>1</mechanicalReduction>
    </actuator>
  </transmission>
  <!-- links: main serial chain -->
  <link name="base_link"/>
  <link name="base_link_inertia">
    <visual>
      <origin rpy="0 0 3.141592653589793" xyz="0 0 0"/>
      <geometry>
        <mesh filename="package://ur_description/meshes/ur10e/collision/base.stl"/>
      </geometry>
      <material name="LightGrey">
        <color rgba="0.7 0.7 0.7 1.0"/>
      </material>
    </visual>
    <collision>
      <origin rpy="0 0 3.141592653589793" xyz="0 0 0"/>
      <geometry>
        <mesh filename="package://ur_description/meshes/ur10e/collision/base.stl"/>
      </geometry>
    </collision>
    <inertial>
      <mass value="4.0"/>
      <origin rpy="0 0 0" xyz="0 0 0"/>
      <inertia ixx="0.0061063308908" ixy="0.0" ixz="0.0" iyy="0.0061063308908" iyz="0.0" izz="0.01125"/>
    </inertial>
  </link>
  <link name="shoulder_link">
    <visual>
      <origin rpy="0 0 3.141592653589793" xyz="0 0 0"/>
      <geometry>
        <mesh filename="package://ur_description/meshes/ur10e/collision/shoulder.stl"/>
      </geometry>
      <material name="LightGrey">
        <color rgba="0.7 0.7 0.7 1.0"/>
      </material>
    </visual>
    <collision>
      <origin rpy="0 0 3.141592653589793" xyz="0 0 0"/>
      <geometry>
        <mesh filename="package://ur_description/meshes/ur10e/collision/shoulder.stl"/>
      </geometry>
    </collision>
    <inertial>
      <mass value="7.369"/>
      <origin rpy="0 0 0" xyz="0 0 0"/>
      <inertia ixx="0.029819260655624295" ixy="0.0" ixz="0.0" iyy="0.029819260655624295" iyz="0.0" izz="0.020725312499999995"/>
    </inertial>
  </link>
  <link name="upper_arm_link">
    <visual>
      <origin rpy="1.5707963267948966 0 -1.5707963267948966" xyz="0 0 0.176"/>
      <geometry>
        <mesh filename="package://ur_description/meshes/ur16e/collision/upperarm.stl"/>
      </geometry>
      <material name="LightGrey">
        <color rgba="0.7 0.7 0.7 1.0"/>
      </material>
    </visual>
    <collision>
      <origin rpy="1.5707963267948966 0 -1.5707963267948966" xyz="0 0 0.176"/>
      <geometry>
        <mesh filename="package://ur_description/meshes/ur16e/collision/upperarm.stl"/>
      </geometry>
    </collision>
    <inertial>
      <mass value="10.45"/>
      <origin rpy="0 1.5707963267948966 0" xyz="-0.2392 0.0 0.175"/>
      <inertia ixx="0.21399985623335657" ixy="0.0" ixz="0.0" iyy="0.21399985623335657" iyz="0.0" izz="0.029390624999999997"/>
    </inertial>
  </link>
  <link name="forearm_link">
    <visual>
      <origin rpy="1.5707963267948966 0 -1.5707963267948966" xyz="0 0 0.04"/>
      <geometry>
        <mesh filename="package://ur_description/meshes/ur16e/collision/forearm.stl"/>
      </geometry>
      <material name="LightGrey">
        <color rgba="0.7 0.7 0.7 1.0"/>
      </material>
    </visual>
    <collision>
      <origin rpy="1.5707963267948966 0 -1.5707963267948966" xyz="0 0 0.04"/>
      <geometry>
        <mesh filename="package://ur_description/meshes/ur16e/collision/forearm.stl"/>
      </geometry>
    </collision>
    <inertial>
      <mass value="4.321"/>
      <origin rpy="0 1.5707963267948966 0" xyz="-0.18 0.0 0.04"/>
      <inertia ixx="0.052743185152717496" ixy="0.0" ixz="0.0" iyy="0.052743185152717496" iyz="0.0" izz="0.012152812499999997"/>
    </inertial>
  </link>
  <link name="wrist_1_link">
    <visual>
      <!-- TODO: Move this to a parameter -->
      <origin rpy="1.5707963267948966 0 0" xyz="0 0 -0.135"/>
      <geometry>
        <mesh filename="package://ur_description/meshes/ur10e/collision/wrist1.stl"/>
      </geometry>
      <material name="LightGrey">
        <color rgba="0.7 0.7 0.7 1.0"/>
      </material>
    </visual>
    <collision>
      <origin rpy="1.5707963267948966 0 0" xyz="0 0 -0.135"/>
      <geometry>
        <mesh filename="package://ur_description/meshes/ur10e/collision/wrist1.stl"/>
      </geometry>
    </collision>
    <inertial>
      <mass value="2.18"/>
      <origin rpy="0 0 0" xyz="0 0 0"/>
      <inertia ixx="0.0056816227273499996" ixy="0.0" ixz="0.0" iyy="0.0056816227273499996" iyz="0.0" izz="0.00613125"/>
    </inertial>
  </link>
  <link name="wrist_2_link">
    <visual>
      <origin rpy="0 0 0" xyz="0 0 -0.12"/>
      <geometry>
        <mesh filename="package://ur_description/meshes/ur10e/collision/wrist2.stl"/>
      </geometry>
      <material name="LightGrey">
        <color rgba="0.7 0.7 0.7 1.0"/>
      </material>
    </visual>
    <collision>
      <origin rpy="0 0 0" xyz="0 0 -0.12"/>
      <geometry>
        <mesh filename="package://ur_description/meshes/ur10e/collision/wrist2.stl"/>
      </geometry>
    </collision>
    <inertial>
      <mass value="2.033"/>
      <origin rpy="0 0 0" xyz="0 0 0"/>
      <inertia ixx="0.0052985041305975" ixy="0.0" ixz="0.0" iyy="0.0052985041305975" iyz="0.0" izz="0.0057178125"/>
    </inertial>
  </link>
  <link name="wrist_3_link">
    <visual>
      <origin rpy="1.5707963267948966 0 0" xyz="0 0 -0.1168"/>
      <geometry>
        <mesh filename="package://ur_description/meshes/ur10e/collision/wrist3.stl"/>
      </geometry>
      <material name="LightGrey">
        <color rgba="0.7 0.7 0.7 1.0"/>
      </material>
    </visual>
    <collision>
      <origin rpy="1.5707963267948966 0 0" xyz="0 0 -0.1168"/>
      <geometry>
        <mesh filename="package://ur_description/meshes/ur10e/collision/wrist3.stl"/>
      </geometry>
    </collision>
    <inertial>
      <mass value="0.907"/>
      <origin rpy="0 0 0" xyz="0.0 0.0 -0.025"/>
      <inertia ixx="0.0006481268240825001" ixy="0.0" ixz="0.0" iyy="0.0006481268240825001" iyz="0.0" izz="0.0009183374999999999"/>
    </inertial>
  </link>
  <!-- joints: main serial chain -->
  <joint name="base_link-base_link_inertia" type="fixed">
    <parent link="base_link"/>
    <child link="base_link_inertia"/>
    <!-- 'base_link' is REP-103 aligned (so X+ forward), while the internal
           frames of the robot/controller have X+ pointing backwards.
           Use the joint between 'base_link' and 'base_link_inertia' (a dummy
           link/frame) to introduce the necessary rotation over Z (of pi rad).
      -->
    <origin rpy="0 0 3.141592653589793" xyz="0 0 0"/>
  </joint>
  <joint name="shoulder_pan_joint" type="revolute">
    <parent link="base_link_inertia"/>
    <child link="shoulder_link"/>
    <origin rpy="0 0 -2.822348106543138e-07" xyz="0 0 0.1809007326690537"/>
    <axis xyz="0 0 1"/>
    <limit effort="330.0" lower="-3.490658503988659" upper="3.490658503988659" velocity="2.0943951023931953"/>
    <dynamics damping="0" friction="0"/>
  </joint>
  <joint name="shoulder_lift_joint" type="revolute">
    <parent link="shoulder_link"/>
    <child link="upper_arm_link"/>
    <origin rpy="1.571090054964591 0 -1.942932784399954e-06" xyz="0.0001707247303410888 0 0"/>
    <axis xyz="0 0 1"/>
    <limit effort="330.0" lower="-4.71238898038469" upper="1.5707963267948966" velocity="2.0943951023931953"/>
    <dynamics damping="0" friction="0"/>
  </joint>
  <joint name="elbow_joint" type="revolute">
    <parent link="upper_arm_link"/>
    <child link="forearm_link"/>
    <origin rpy="3.141100797874045 -3.139778714510265 -3.141588063772322" xyz="-0.4781972217758275 0 0"/>
    <axis xyz="0 0 1"/>
    <limit effort="150.0" lower="-3.141592653589793" upper="3.141592653589793" velocity="3.141592653589793"/>
    <dynamics damping="0" friction="0"/>
  </joint>
  <joint name="wrist_1_joint" type="revolute">
    <parent link="forearm_link"/>
    <child link="wrist_1_link"/>
    <origin rpy="0.005293674345160438 0.001470478723854599 -9.304969222818502e-06" xyz="-0.3598771763408388 -0.0009172308826420315 0.1732676124315309"/>
    <axis xyz="0 0 1"/>
    <limit effort="56.0" lower="-3.490658503988659" upper="3.490658503988659" velocity="3.141592653589793"/>
    <dynamics damping="0" friction="0"/>
  </joint>
  <joint name="wrist_2_joint" type="revolute">
    <parent link="wrist_1_link"/>
    <child link="wrist_2_link"/>
    <origin rpy="1.568926004752046 0 1.385827384008109e-06" xyz="0.0001656662300944413 -0.1197860097975219 0.000224038675786347"/>
    <axis xyz="0 0 1"/>
    <limit effort="56.0" lower="-3.490658503988659" upper="3.490658503988659" velocity="3.141592653589793"/>
    <dynamics damping="0" friction="0"/>
  </joint>
  <joint name="wrist_3_joint" type="revolute">
    <parent link="wrist_2_link"/>
    <child link="wrist_3_link"/>
    <origin rpy="1.570746071216452 3.141592653589793 3.141592624949271" xyz="-4.282547685928057e-05 0.1155358116742619 -5.80631905160188e-06"/>
    <axis xyz="0 0 1"/>
    <limit effort="56.0" lower="-6.283185307179586" upper="6.283185307179586" velocity="3.141592653589793"/>
    <dynamics damping="0" friction="0"/>
  </joint>
  <!-- ROS-Industrial 'base' frame: base_link to UR 'Base' Coordinates transform -->
  <link name="base"/>
  <joint name="base_link-base_fixed_joint" type="fixed">
    <!-- Note the rotation over Z of pi radians: as base_link is REP-103
           aligned (ie: has X+ forward, Y+ left and Z+ up), this is needed
           to correctly align 'base' with the 'Base' coordinate system of
           the UR controller.
      -->
    <origin rpy="0 0 3.141592653589793" xyz="0 0 0"/>
    <parent link="base_link"/>
    <child link="base"/>
  </joint>
  <!-- ROS-Industrial 'flange' frame: attachment point for EEF models -->
  <link name="flange"/>
  <joint name="wrist_3-flange" type="fixed">
    <parent link="wrist_3_link"/>
    <child link="flange"/>
    <origin rpy="0 -1.5707963267948966 -1.5707963267948966" xyz="0 0 0"/>
  </joint>
  <!-- ROS-Industrial 'tool0' frame: all-zeros tool frame -->
  <link name="tool0"/>
  <joint name="flange-tool0" type="fixed">
    <!-- default toolframe: X+ left, Y+ up, Z+ front -->
    <origin rpy="1.5707963267948966 0 1.5707963267948966" xyz="0 0 0"/>
    <parent link="flange"/>
    <child link="tool0"/>
  </joint>
  <joint name="ur" type="fixed">
    <parent link="cuña_tool0"/>
    <child link="base_link"/>
    <origin rpy="0 0 0" xyz="0 0 0"/>
  </joint>
  <link name="zivid_extender_base_link">
    <visual>
      <geometry>
        <mesh filename="package://converging_polishing_workcell/meshes/collision/Zivid_mount_extender_OA01E.stl"/>
      </geometry>
    </visual>
    <collision>
      <geometry>
        <mesh filename="package://converging_polishing_workcell/meshes/collision/Zivid_mount_extender_OA01E.stl"/>
      </geometry>
    </collision>
  </link>
  <link name="zivid_extender_tool0"/>
  <joint name="zivid_extender_tool0" type="fixed">
    <parent link="zivid_extender_base_link"/>
    <child link="zivid_extender_tool0"/>
    <origin xyz="0 0 0.072"/>
  </joint>
  <joint name="extender" type="fixed">
    <parent link="tool0"/>
    <child link="zivid_extender_base_link"/>
  </joint>
  <link name="mount_base_link">
    <visual>
      <geometry>
        <mesh filename="package://converging_polishing_workcell/meshes/collision/converging_mount.stl"/>
      </geometry>
      <material name="gray">
        <color rgba="0.5 0.5 0.5 1"/>
      </material>
    </visual>
    <collision>
      <geometry>
        <mesh filename="package://converging_polishing_workcell/meshes/collision/converging_mount.stl"/>
      </geometry>
    </collision>
  </link>
  <link name="mount_tool0"/>
  <joint name="mount_tool0" type="fixed">
    <parent link="mount_base_link"/>
    <child link="mount_tool0"/>
    <origin xyz="0 0 0.0125"/>
  </joint>
  <link name="mount_tool1"/>
  <joint name="mount_tool1" type="fixed">
    <parent link="mount_base_link"/>
    <child link="mount_tool1"/>
    <origin rpy="-1.5707963267948966 0 0" xyz="0 0.049 0.044"/>
  </joint>
  <joint name="mount" type="fixed">
    <parent link="zivid_extender_tool0"/>
    <child link="mount_base_link"/>
    <origin rpy="0 0 -1.5707963267948966" xyz="0 0 0"/>
  </joint>
  <link name="zivid_base_link">
    <visual>
      <geometry>
        <mesh filename="package://converging_polishing_workcell/meshes/collision/Zivid_mount_OA121.stl"/>
      </geometry>
    </visual>
    <collision>
      <geometry>
        <mesh filename="package://converging_polishing_workcell/meshes/collision/Zivid_mount_OA121.stl"/>
      </geometry>
    </collision>
  </link>
  <link name="zivid_tool0"/>
  <joint name="zivid_tool0" type="fixed">
    <parent link="zivid_base_link"/>
    <child link="zivid_tool0"/>
    <origin rpy="0 0 0" xyz="0 0 0.0125"/>
  </joint>
  <link name="zivid_protective_housing">
    <visual>
      <geometry>
        <mesh filename="package://converging_polishing_workcell/meshes/collision/ZividTwo_protective_housing.stl"/>
      </geometry>
    </visual>
    <collision>
      <geometry>
        <mesh filename="package://converging_polishing_workcell/meshes/collision/ZividTwo_protective_housing.stl"/>
      </geometry>
    </collision>
  </link>
  <joint name="zivid_protective_housing" type="fixed">
    <parent link="zivid_base_link"/>
    <child link="zivid_protective_housing"/>
    <origin rpy="-1.8325957145940461 0 0" xyz="0 0.0742 0.0225"/>
  </joint>
  <link name="zivid_camera">
    <visual>
      <geometry>
        <mesh filename="package://converging_polishing_workcell/meshes/collision/ZividTwo.stl"/>
      </geometry>
    </visual>
    <collision>
      <geometry>
        <mesh filename="package://converging_polishing_workcell/meshes/collision/ZividTwo.stl"/>
      </geometry>
    </collision>
  </link>
  <joint name="zivid_camera" type="fixed">
    <parent link="zivid_protective_housing"/>
    <child link="zivid_camera"/>
    <origin rpy="0 0 0" xyz="0 0 0.01"/>
  </joint>
  <link name="zivid_optical_frame"/>
  <joint name="{prefix}optical_frame" type="fixed">
    <parent link="zivid_camera"/>
    <child link="zivid_optical_frame"/>
    <!-- Values from https://support.zivid.com/en/latest/reference-articles/camera-coordinate-system.html -->
    <origin rpy="-1.5707963267948966 0 3.141592653589793" xyz="0.05584 -0.02302 0.0295"/>
  </joint>
  <joint name="zivid" type="fixed">
    <parent link="mount_tool0"/>
    <child link="zivid_base_link"/>
    <origin rpy="0 0 3.141592653589793" xyz="0 0 0"/>
  </joint>
  <link name="acople_base_link">
    <visual>
      <geometry>
        <mesh filename="package://converging_polishing_workcell/meshes/collision/acople_mirka_ur.stl"/>
      </geometry>
      <material name="color">
        <color rgba="0.2 0.2 0.2 1"/>
      </material>
    </visual>
    <collision>
      <geometry>
        <mesh filename="package://converging_polishing_workcell/meshes/collision/acople_mirka_ur.stl"/>
      </geometry>
    </collision>
  </link>
  <link name="acople_tool0"/>
  <joint name="acople_tool0" type="fixed">
    <parent link="acople_base_link"/>
    <child link="acople_tool0"/>
    <origin xyz="0 0 0.0185"/>
  </joint>
  <joint name="acople" type="fixed">
    <parent link="mount_tool1"/>
    <child link="acople_base_link"/>
    <origin rpy="0 0 3.141592653589793" xyz="0 0 0"/>
  </joint>
  <link name="mirka_base_link">
    <visual>
      <geometry>
        <mesh filename="package://mirka_description/meshes/collision/airos-150nv.stl"/>
      </geometry>
    </visual>
    <collision>
      <geometry>
        <mesh filename="package://mirka_description/meshes/collision/airos-150nv.stl"/>
      </geometry>
    </collision>
  </link>
  <link name="mirka_tool0"/>
  <joint name="mirka_tool0" type="fixed">
    <parent link="mirka_base_link"/>
    <origin rpy="0 0 0" xyz="0 0 0.107 "/>
    <child link="mirka_tool0"/>
  </joint>
  <joint name="mirka" type="fixed">
    <parent link="acople_tool0"/>
    <child link="mirka_base_link"/>
  </joint>
  <link name="things_on_table">
    <visual>
      <geometry>
        <box size="0.3 0.4 0.2"/>
      </geometry>
      <material name="gray">
        <color rgba="0.5 0.5 0.5 1"/>
      </material>
    </visual>
    <collision>
      <geometry>
        <box size="0.3 0.4 0.2"/>
      </geometry>
    </collision>
  </link>
  <joint name="things" type="fixed">
    <parent link="table"/>
    <child link="things_on_table"/>
    <origin rpy="0 0 0.0" xyz="0.95 0.3 0.1"/>
  </joint>
  <!-- plane calibrated using the ur with origin in 45cm,45cm of the grid on the table
    moved other things around to make the world frame equal the grid on the table-->
  <link name="calibrated_table"/>
  <joint name="table_calibration" type="fixed">
    <parent link="base"/>
    <child link="calibrated_table"/>
    <origin rpy="2.0943951023931953 0 -1.5707963267948966" xyz="0.69992 -0.00844 0.82107"/>
  </joint>
  <!-- tool calibrated using the ur-->
  <!-- <link name="mirka_tool0"/>
  <joint name="mirka_calibration" type="fixed">
    <parent link="tool0"/>
    <child link="mirka_tool0" />
    <origin xyz="0.096 0.091 0.104" rpy="${radians(-172.041)} ${radians(-89.998)} ${radians(37.043)}" />
  </joint> -->
</robot>
